[2024-03-17 17:14:46,844] {/home/raziel/projects/psycalc/temporistics_matching_algorithm/app/routes.py:61} ERROR - An error occurred: 'NoneType' object is not callable
[2024-09-14 15:24:25,388] {/home/raziel/projects/psycalc/temporistics_matching_algorithm/env/lib/python3.9/site-packages/flask/app.py:838} ERROR - Exception on /calculate [POST]
Traceback (most recent call last):
  File "/home/raziel/projects/psycalc/temporistics_matching_algorithm/env/lib/python3.9/site-packages/flask/app.py", line 1473, in wsgi_app
    response = self.full_dispatch_request()
  File "/home/raziel/projects/psycalc/temporistics_matching_algorithm/env/lib/python3.9/site-packages/flask/app.py", line 882, in full_dispatch_request
    rv = self.handle_user_exception(e)
  File "/home/raziel/projects/psycalc/temporistics_matching_algorithm/env/lib/python3.9/site-packages/flask/app.py", line 880, in full_dispatch_request
    rv = self.dispatch_request()
  File "/home/raziel/projects/psycalc/temporistics_matching_algorithm/env/lib/python3.9/site-packages/flask/app.py", line 865, in dispatch_request
    return self.ensure_sync(self.view_functions[rule.endpoint])(**view_args)  # type: ignore[no-any-return]
  File "/home/raziel/projects/psycalc/temporistics_matching_algorithm/app/routes.py", line 58, in calculate
    relationship_type, comfort_score = calculate_relationship(user1_type, user2_type, typology_name)
  File "/home/raziel/projects/psycalc/temporistics_matching_algorithm/app/services.py", line 34, in calculate_relationship
    relationship_type = typology_instance.determine_relationship_type(user1, user2)
AttributeError: 'TypologyTemporistics' object has no attribute 'determine_relationship_type'
[2024-09-14 15:24:42,421] {/home/raziel/projects/psycalc/temporistics_matching_algorithm/env/lib/python3.9/site-packages/flask/app.py:838} ERROR - Exception on /calculate [POST]
Traceback (most recent call last):
  File "/home/raziel/projects/psycalc/temporistics_matching_algorithm/env/lib/python3.9/site-packages/flask/app.py", line 1473, in wsgi_app
    response = self.full_dispatch_request()
  File "/home/raziel/projects/psycalc/temporistics_matching_algorithm/env/lib/python3.9/site-packages/flask/app.py", line 882, in full_dispatch_request
    rv = self.handle_user_exception(e)
  File "/home/raziel/projects/psycalc/temporistics_matching_algorithm/env/lib/python3.9/site-packages/flask/app.py", line 880, in full_dispatch_request
    rv = self.dispatch_request()
  File "/home/raziel/projects/psycalc/temporistics_matching_algorithm/env/lib/python3.9/site-packages/flask/app.py", line 865, in dispatch_request
    return self.ensure_sync(self.view_functions[rule.endpoint])(**view_args)  # type: ignore[no-any-return]
  File "/home/raziel/projects/psycalc/temporistics_matching_algorithm/app/routes.py", line 58, in calculate
    relationship_type, comfort_score = calculate_relationship(user1_type, user2_type, typology_name)
  File "/home/raziel/projects/psycalc/temporistics_matching_algorithm/app/services.py", line 34, in calculate_relationship
    relationship_type = typology_instance.determine_relationship_type(user1, user2)
AttributeError: 'TypologyTemporistics' object has no attribute 'determine_relationship_type'
[2024-09-14 15:29:21,332] {/home/raziel/projects/psycalc/temporistics_matching_algorithm/env/lib/python3.9/site-packages/flask/app.py:838} ERROR - Exception on /calculate [POST]
Traceback (most recent call last):
  File "/home/raziel/projects/psycalc/temporistics_matching_algorithm/env/lib/python3.9/site-packages/flask/app.py", line 1473, in wsgi_app
    response = self.full_dispatch_request()
  File "/home/raziel/projects/psycalc/temporistics_matching_algorithm/env/lib/python3.9/site-packages/flask/app.py", line 882, in full_dispatch_request
    rv = self.handle_user_exception(e)
  File "/home/raziel/projects/psycalc/temporistics_matching_algorithm/env/lib/python3.9/site-packages/flask/app.py", line 880, in full_dispatch_request
    rv = self.dispatch_request()
  File "/home/raziel/projects/psycalc/temporistics_matching_algorithm/env/lib/python3.9/site-packages/flask/app.py", line 865, in dispatch_request
    return self.ensure_sync(self.view_functions[rule.endpoint])(**view_args)  # type: ignore[no-any-return]
  File "/home/raziel/projects/psycalc/temporistics_matching_algorithm/app/routes.py", line 58, in calculate
    relationship_type, comfort_score = calculate_relationship(user1_type, user2_type, typology_name)
  File "/home/raziel/projects/psycalc/temporistics_matching_algorithm/app/services.py", line 34, in calculate_relationship
    relationship_type = typology_instance.determine_relationship_type(user1, user2)
AttributeError: 'TypologyTemporistics' object has no attribute 'determine_relationship_type'
[2024-09-14 15:47:11,007] {/home/raziel/projects/psycalc/temporistics_matching_algorithm/env/lib/python3.9/site-packages/flask/app.py:838} ERROR - Exception on /calculate [POST]
Traceback (most recent call last):
  File "/home/raziel/projects/psycalc/temporistics_matching_algorithm/env/lib/python3.9/site-packages/flask/app.py", line 1473, in wsgi_app
    response = self.full_dispatch_request()
  File "/home/raziel/projects/psycalc/temporistics_matching_algorithm/env/lib/python3.9/site-packages/flask/app.py", line 882, in full_dispatch_request
    rv = self.handle_user_exception(e)
  File "/home/raziel/projects/psycalc/temporistics_matching_algorithm/env/lib/python3.9/site-packages/flask/app.py", line 880, in full_dispatch_request
    rv = self.dispatch_request()
  File "/home/raziel/projects/psycalc/temporistics_matching_algorithm/env/lib/python3.9/site-packages/flask/app.py", line 865, in dispatch_request
    return self.ensure_sync(self.view_functions[rule.endpoint])(**view_args)  # type: ignore[no-any-return]
  File "/home/raziel/projects/psycalc/temporistics_matching_algorithm/app/routes.py", line 58, in calculate
    relationship_type, comfort_score = calculate_relationship(user1_type, user2_type, typology_name)
  File "/home/raziel/projects/psycalc/temporistics_matching_algorithm/app/services.py", line 37, in calculate_relationship
    comfort_score, _ = typology_instance.get_comfort_score(relationship_type)
AttributeError: 'TypologyTemporistics' object has no attribute 'get_comfort_score'
[2024-09-14 13:25:14,788] {/usr/local/lib/python3.8/site-packages/flask/app.py:1891} ERROR - Exception on /login [POST]
Traceback (most recent call last):
  File "/usr/local/lib/python3.8/site-packages/sqlalchemy/util/_collections.py", line 1020, in __call__
    return self.registry[key]
KeyError: 140018653255488

During handling of the above exception, another exception occurred:

Traceback (most recent call last):
  File "/usr/local/lib/python3.8/site-packages/flask/app.py", line 2447, in wsgi_app
    response = self.full_dispatch_request()
  File "/usr/local/lib/python3.8/site-packages/flask/app.py", line 1952, in full_dispatch_request
    rv = self.handle_user_exception(e)
  File "/usr/local/lib/python3.8/site-packages/flask/app.py", line 1821, in handle_user_exception
    reraise(exc_type, exc_value, tb)
  File "/usr/local/lib/python3.8/site-packages/flask/_compat.py", line 39, in reraise
    raise value
  File "/usr/local/lib/python3.8/site-packages/flask/app.py", line 1950, in full_dispatch_request
    rv = self.dispatch_request()
  File "/usr/local/lib/python3.8/site-packages/flask/app.py", line 1936, in dispatch_request
    return self.view_functions[rule.endpoint](**req.view_args)
  File "/app/app/routes.py", line 102, in login
    user = User.query.filter_by(email=form.email.data).first()
  File "/usr/local/lib/python3.8/site-packages/flask_sqlalchemy/__init__.py", line 552, in __get__
    return type.query_class(mapper, session=self.sa.session())
  File "/usr/local/lib/python3.8/site-packages/sqlalchemy/orm/scoping.py", line 78, in __call__
    return self.registry()
  File "/usr/local/lib/python3.8/site-packages/sqlalchemy/util/_collections.py", line 1022, in __call__
    return self.registry.setdefault(key, self.createfunc())
  File "/usr/local/lib/python3.8/site-packages/sqlalchemy/orm/session.py", line 3309, in __call__
    return self.class_(**local_kw)
  File "/usr/local/lib/python3.8/site-packages/flask_sqlalchemy/__init__.py", line 176, in __init__
    bind = options.pop('bind', None) or db.engine
  File "/usr/local/lib/python3.8/site-packages/flask_sqlalchemy/__init__.py", line 998, in engine
    return self.get_engine()
  File "/usr/local/lib/python3.8/site-packages/flask_sqlalchemy/__init__.py", line 1017, in get_engine
    return connector.get_engine()
  File "/usr/local/lib/python3.8/site-packages/flask_sqlalchemy/__init__.py", line 594, in get_engine
    self._engine = rv = self._sa.create_engine(sa_url, options)
  File "/usr/local/lib/python3.8/site-packages/flask_sqlalchemy/__init__.py", line 1027, in create_engine
    return sqlalchemy.create_engine(sa_url, **engine_opts)
  File "/usr/local/lib/python3.8/site-packages/sqlalchemy/engine/__init__.py", line 525, in create_engine
    return strategy.create(*args, **kwargs)
  File "/usr/local/lib/python3.8/site-packages/sqlalchemy/engine/strategies.py", line 87, in create
    dbapi = dialect_cls.dbapi(**dbapi_args)
  File "/usr/local/lib/python3.8/site-packages/sqlalchemy/dialects/postgresql/psycopg2.py", line 792, in dbapi
    import psycopg2
ModuleNotFoundError: No module named 'psycopg2'
[2024-09-14 13:26:26,726] {/usr/local/lib/python3.8/site-packages/flask/app.py:1891} ERROR - Exception on /login [POST]
Traceback (most recent call last):
  File "/usr/local/lib/python3.8/site-packages/sqlalchemy/util/_collections.py", line 1020, in __call__
    return self.registry[key]
KeyError: 140018653255488

During handling of the above exception, another exception occurred:

Traceback (most recent call last):
  File "/usr/local/lib/python3.8/site-packages/flask/app.py", line 2447, in wsgi_app
    response = self.full_dispatch_request()
  File "/usr/local/lib/python3.8/site-packages/flask/app.py", line 1952, in full_dispatch_request
    rv = self.handle_user_exception(e)
  File "/usr/local/lib/python3.8/site-packages/flask/app.py", line 1821, in handle_user_exception
    reraise(exc_type, exc_value, tb)
  File "/usr/local/lib/python3.8/site-packages/flask/_compat.py", line 39, in reraise
    raise value
  File "/usr/local/lib/python3.8/site-packages/flask/app.py", line 1950, in full_dispatch_request
    rv = self.dispatch_request()
  File "/usr/local/lib/python3.8/site-packages/flask/app.py", line 1936, in dispatch_request
    return self.view_functions[rule.endpoint](**req.view_args)
  File "/app/app/routes.py", line 102, in login
    user = User.query.filter_by(email=form.email.data).first()
  File "/usr/local/lib/python3.8/site-packages/flask_sqlalchemy/__init__.py", line 552, in __get__
    return type.query_class(mapper, session=self.sa.session())
  File "/usr/local/lib/python3.8/site-packages/sqlalchemy/orm/scoping.py", line 78, in __call__
    return self.registry()
  File "/usr/local/lib/python3.8/site-packages/sqlalchemy/util/_collections.py", line 1022, in __call__
    return self.registry.setdefault(key, self.createfunc())
  File "/usr/local/lib/python3.8/site-packages/sqlalchemy/orm/session.py", line 3309, in __call__
    return self.class_(**local_kw)
  File "/usr/local/lib/python3.8/site-packages/flask_sqlalchemy/__init__.py", line 176, in __init__
    bind = options.pop('bind', None) or db.engine
  File "/usr/local/lib/python3.8/site-packages/flask_sqlalchemy/__init__.py", line 998, in engine
    return self.get_engine()
  File "/usr/local/lib/python3.8/site-packages/flask_sqlalchemy/__init__.py", line 1017, in get_engine
    return connector.get_engine()
  File "/usr/local/lib/python3.8/site-packages/flask_sqlalchemy/__init__.py", line 594, in get_engine
    self._engine = rv = self._sa.create_engine(sa_url, options)
  File "/usr/local/lib/python3.8/site-packages/flask_sqlalchemy/__init__.py", line 1027, in create_engine
    return sqlalchemy.create_engine(sa_url, **engine_opts)
  File "/usr/local/lib/python3.8/site-packages/sqlalchemy/engine/__init__.py", line 525, in create_engine
    return strategy.create(*args, **kwargs)
  File "/usr/local/lib/python3.8/site-packages/sqlalchemy/engine/strategies.py", line 87, in create
    dbapi = dialect_cls.dbapi(**dbapi_args)
  File "/usr/local/lib/python3.8/site-packages/sqlalchemy/dialects/postgresql/psycopg2.py", line 792, in dbapi
    import psycopg2
ModuleNotFoundError: No module named 'psycopg2'
[2024-09-14 13:29:12,718] {/usr/local/lib/python3.8/site-packages/flask/app.py:1891} ERROR - Exception on /login [POST]
Traceback (most recent call last):
  File "/usr/local/lib/python3.8/site-packages/sqlalchemy/engine/base.py", line 1276, in _execute_context
    self.dialect.do_execute(
  File "/usr/local/lib/python3.8/site-packages/sqlalchemy/engine/default.py", line 608, in do_execute
    cursor.execute(statement, parameters)
psycopg2.errors.UndefinedTable: relation "user" does not exist
LINE 2: FROM "user" 
             ^


The above exception was the direct cause of the following exception:

Traceback (most recent call last):
  File "/usr/local/lib/python3.8/site-packages/flask/app.py", line 2447, in wsgi_app
    response = self.full_dispatch_request()
  File "/usr/local/lib/python3.8/site-packages/flask/app.py", line 1952, in full_dispatch_request
    rv = self.handle_user_exception(e)
  File "/usr/local/lib/python3.8/site-packages/flask/app.py", line 1821, in handle_user_exception
    reraise(exc_type, exc_value, tb)
  File "/usr/local/lib/python3.8/site-packages/flask/_compat.py", line 39, in reraise
    raise value
  File "/usr/local/lib/python3.8/site-packages/flask/app.py", line 1950, in full_dispatch_request
    rv = self.dispatch_request()
  File "/usr/local/lib/python3.8/site-packages/flask/app.py", line 1936, in dispatch_request
    return self.view_functions[rule.endpoint](**req.view_args)
  File "/app/app/routes.py", line 102, in login
    user = User.query.filter_by(email=form.email.data).first()
  File "/usr/local/lib/python3.8/site-packages/sqlalchemy/orm/query.py", line 3429, in first
    ret = list(self[0:1])
  File "/usr/local/lib/python3.8/site-packages/sqlalchemy/orm/query.py", line 3203, in __getitem__
    return list(res)
  File "/usr/local/lib/python3.8/site-packages/sqlalchemy/orm/query.py", line 3535, in __iter__
    return self._execute_and_instances(context)
  File "/usr/local/lib/python3.8/site-packages/sqlalchemy/orm/query.py", line 3560, in _execute_and_instances
    result = conn.execute(querycontext.statement, self._params)
  File "/usr/local/lib/python3.8/site-packages/sqlalchemy/engine/base.py", line 1011, in execute
    return meth(self, multiparams, params)
  File "/usr/local/lib/python3.8/site-packages/sqlalchemy/sql/elements.py", line 298, in _execute_on_connection
    return connection._execute_clauseelement(self, multiparams, params)
  File "/usr/local/lib/python3.8/site-packages/sqlalchemy/engine/base.py", line 1124, in _execute_clauseelement
    ret = self._execute_context(
  File "/usr/local/lib/python3.8/site-packages/sqlalchemy/engine/base.py", line 1316, in _execute_context
    self._handle_dbapi_exception(
  File "/usr/local/lib/python3.8/site-packages/sqlalchemy/engine/base.py", line 1510, in _handle_dbapi_exception
    util.raise_(
  File "/usr/local/lib/python3.8/site-packages/sqlalchemy/util/compat.py", line 182, in raise_
    raise exception
  File "/usr/local/lib/python3.8/site-packages/sqlalchemy/engine/base.py", line 1276, in _execute_context
    self.dialect.do_execute(
  File "/usr/local/lib/python3.8/site-packages/sqlalchemy/engine/default.py", line 608, in do_execute
    cursor.execute(statement, parameters)
sqlalchemy.exc.ProgrammingError: (psycopg2.errors.UndefinedTable) relation "user" does not exist
LINE 2: FROM "user" 
             ^

[SQL: SELECT "user".id AS user_id, "user".username AS user_username, "user".email AS user_email, "user".password_hash AS user_password_hash 
FROM "user" 
WHERE "user".email = %(email_1)s 
 LIMIT %(param_1)s]
[parameters: {'email_1': 'test@test.com', 'param_1': 1}]
(Background on this error at: http://sqlalche.me/e/13/f405)
[2024-09-14 13:29:58,044] {/usr/local/lib/python3.8/site-packages/flask/app.py:1891} ERROR - Exception on /login [POST]
Traceback (most recent call last):
  File "/usr/local/lib/python3.8/site-packages/sqlalchemy/engine/base.py", line 1276, in _execute_context
    self.dialect.do_execute(
  File "/usr/local/lib/python3.8/site-packages/sqlalchemy/engine/default.py", line 608, in do_execute
    cursor.execute(statement, parameters)
psycopg2.errors.UndefinedTable: relation "user" does not exist
LINE 2: FROM "user" 
             ^


The above exception was the direct cause of the following exception:

Traceback (most recent call last):
  File "/usr/local/lib/python3.8/site-packages/flask/app.py", line 2447, in wsgi_app
    response = self.full_dispatch_request()
  File "/usr/local/lib/python3.8/site-packages/flask/app.py", line 1952, in full_dispatch_request
    rv = self.handle_user_exception(e)
  File "/usr/local/lib/python3.8/site-packages/flask/app.py", line 1821, in handle_user_exception
    reraise(exc_type, exc_value, tb)
  File "/usr/local/lib/python3.8/site-packages/flask/_compat.py", line 39, in reraise
    raise value
  File "/usr/local/lib/python3.8/site-packages/flask/app.py", line 1950, in full_dispatch_request
    rv = self.dispatch_request()
  File "/usr/local/lib/python3.8/site-packages/flask/app.py", line 1936, in dispatch_request
    return self.view_functions[rule.endpoint](**req.view_args)
  File "/app/app/routes.py", line 102, in login
    user = User.query.filter_by(email=form.email.data).first()
  File "/usr/local/lib/python3.8/site-packages/sqlalchemy/orm/query.py", line 3429, in first
    ret = list(self[0:1])
  File "/usr/local/lib/python3.8/site-packages/sqlalchemy/orm/query.py", line 3203, in __getitem__
    return list(res)
  File "/usr/local/lib/python3.8/site-packages/sqlalchemy/orm/query.py", line 3535, in __iter__
    return self._execute_and_instances(context)
  File "/usr/local/lib/python3.8/site-packages/sqlalchemy/orm/query.py", line 3560, in _execute_and_instances
    result = conn.execute(querycontext.statement, self._params)
  File "/usr/local/lib/python3.8/site-packages/sqlalchemy/engine/base.py", line 1011, in execute
    return meth(self, multiparams, params)
  File "/usr/local/lib/python3.8/site-packages/sqlalchemy/sql/elements.py", line 298, in _execute_on_connection
    return connection._execute_clauseelement(self, multiparams, params)
  File "/usr/local/lib/python3.8/site-packages/sqlalchemy/engine/base.py", line 1124, in _execute_clauseelement
    ret = self._execute_context(
  File "/usr/local/lib/python3.8/site-packages/sqlalchemy/engine/base.py", line 1316, in _execute_context
    self._handle_dbapi_exception(
  File "/usr/local/lib/python3.8/site-packages/sqlalchemy/engine/base.py", line 1510, in _handle_dbapi_exception
    util.raise_(
  File "/usr/local/lib/python3.8/site-packages/sqlalchemy/util/compat.py", line 182, in raise_
    raise exception
  File "/usr/local/lib/python3.8/site-packages/sqlalchemy/engine/base.py", line 1276, in _execute_context
    self.dialect.do_execute(
  File "/usr/local/lib/python3.8/site-packages/sqlalchemy/engine/default.py", line 608, in do_execute
    cursor.execute(statement, parameters)
sqlalchemy.exc.ProgrammingError: (psycopg2.errors.UndefinedTable) relation "user" does not exist
LINE 2: FROM "user" 
             ^

[SQL: SELECT "user".id AS user_id, "user".username AS user_username, "user".email AS user_email, "user".password_hash AS user_password_hash 
FROM "user" 
WHERE "user".email = %(email_1)s 
 LIMIT %(param_1)s]
[parameters: {'email_1': 'test@test.com', 'param_1': 1}]
(Background on this error at: http://sqlalche.me/e/13/f405)
[2024-09-14 15:03:07,508] {/usr/local/lib/python3.8/site-packages/flask/app.py:1891} ERROR - Exception on / [GET]
Traceback (most recent call last):
  File "/usr/local/lib/python3.8/site-packages/flask/app.py", line 2447, in wsgi_app
    response = self.full_dispatch_request()
  File "/usr/local/lib/python3.8/site-packages/flask/app.py", line 1952, in full_dispatch_request
    rv = self.handle_user_exception(e)
  File "/usr/local/lib/python3.8/site-packages/flask/app.py", line 1821, in handle_user_exception
    reraise(exc_type, exc_value, tb)
  File "/usr/local/lib/python3.8/site-packages/flask/_compat.py", line 39, in reraise
    raise value
  File "/usr/local/lib/python3.8/site-packages/flask/app.py", line 1950, in full_dispatch_request
    rv = self.dispatch_request()
  File "/usr/local/lib/python3.8/site-packages/flask/app.py", line 1936, in dispatch_request
    return self.view_functions[rule.endpoint](**req.view_args)
  File "/app/app/routes.py", line 64, in index
    return render_template('index.html', types=types, form=form)
  File "/usr/local/lib/python3.8/site-packages/flask/templating.py", line 137, in render_template
    return _render(
  File "/usr/local/lib/python3.8/site-packages/flask/templating.py", line 120, in _render
    rv = template.render(context)
  File "/usr/local/lib/python3.8/site-packages/jinja2/environment.py", line 1090, in render
    self.environment.handle_exception()
  File "/usr/local/lib/python3.8/site-packages/jinja2/environment.py", line 832, in handle_exception
    reraise(*rewrite_traceback_stack(source=source))
  File "/usr/local/lib/python3.8/site-packages/jinja2/_compat.py", line 28, in reraise
    raise value.with_traceback(tb)
  File "/app/app/templates/index.html", line 1, in top-level template code
    {% extends 'base.html' %}
  File "/app/app/templates/base.html", line 14, in top-level template code
    <a class="nav-link" href="{{ url_for('main.user_profile') }}">Profile</a>
  File "/usr/local/lib/python3.8/site-packages/flask/helpers.py", line 370, in url_for
    return appctx.app.handle_url_build_error(error, endpoint, values)
  File "/usr/local/lib/python3.8/site-packages/flask/app.py", line 2216, in handle_url_build_error
    reraise(exc_type, exc_value, tb)
  File "/usr/local/lib/python3.8/site-packages/flask/_compat.py", line 39, in reraise
    raise value
  File "/usr/local/lib/python3.8/site-packages/flask/helpers.py", line 357, in url_for
    rv = url_adapter.build(
  File "/usr/local/lib/python3.8/site-packages/werkzeug/routing.py", line 2179, in build
    raise BuildError(endpoint, values, method, self)
werkzeug.routing.BuildError: Could not build url for endpoint 'main.user_profile'. Did you forget to specify values ['username']?
[2024-09-14 15:10:02,497] {/usr/local/lib/python3.8/site-packages/flask/app.py:1891} ERROR - Exception on / [GET]
Traceback (most recent call last):
  File "/usr/local/lib/python3.8/site-packages/flask/app.py", line 2447, in wsgi_app
    response = self.full_dispatch_request()
  File "/usr/local/lib/python3.8/site-packages/flask/app.py", line 1952, in full_dispatch_request
    rv = self.handle_user_exception(e)
  File "/usr/local/lib/python3.8/site-packages/flask/app.py", line 1821, in handle_user_exception
    reraise(exc_type, exc_value, tb)
  File "/usr/local/lib/python3.8/site-packages/flask/_compat.py", line 39, in reraise
    raise value
  File "/usr/local/lib/python3.8/site-packages/flask/app.py", line 1950, in full_dispatch_request
    rv = self.dispatch_request()
  File "/usr/local/lib/python3.8/site-packages/flask/app.py", line 1936, in dispatch_request
    return self.view_functions[rule.endpoint](**req.view_args)
  File "/app/app/routes.py", line 64, in index
    return render_template('index.html', types=types, form=form)
  File "/usr/local/lib/python3.8/site-packages/flask/templating.py", line 137, in render_template
    return _render(
  File "/usr/local/lib/python3.8/site-packages/flask/templating.py", line 120, in _render
    rv = template.render(context)
  File "/usr/local/lib/python3.8/site-packages/jinja2/environment.py", line 1090, in render
    self.environment.handle_exception()
  File "/usr/local/lib/python3.8/site-packages/jinja2/environment.py", line 832, in handle_exception
    reraise(*rewrite_traceback_stack(source=source))
  File "/usr/local/lib/python3.8/site-packages/jinja2/_compat.py", line 28, in reraise
    raise value.with_traceback(tb)
  File "/app/app/templates/index.html", line 1, in top-level template code
    {% extends 'base.html' %}
  File "/app/app/templates/base.html", line 14, in top-level template code
    <a class="nav-link" href="{{ url_for('main.user_profile') }}">Profile</a>
  File "/usr/local/lib/python3.8/site-packages/flask/helpers.py", line 370, in url_for
    return appctx.app.handle_url_build_error(error, endpoint, values)
  File "/usr/local/lib/python3.8/site-packages/flask/app.py", line 2216, in handle_url_build_error
    reraise(exc_type, exc_value, tb)
  File "/usr/local/lib/python3.8/site-packages/flask/_compat.py", line 39, in reraise
    raise value
  File "/usr/local/lib/python3.8/site-packages/flask/helpers.py", line 357, in url_for
    rv = url_adapter.build(
  File "/usr/local/lib/python3.8/site-packages/werkzeug/routing.py", line 2179, in build
    raise BuildError(endpoint, values, method, self)
werkzeug.routing.BuildError: Could not build url for endpoint 'main.user_profile'. Did you forget to specify values ['username']?
[2024-09-14 15:10:46,739] {/usr/local/lib/python3.8/site-packages/flask/app.py:1891} ERROR - Exception on / [GET]
Traceback (most recent call last):
  File "/usr/local/lib/python3.8/site-packages/flask/app.py", line 2447, in wsgi_app
    response = self.full_dispatch_request()
  File "/usr/local/lib/python3.8/site-packages/flask/app.py", line 1952, in full_dispatch_request
    rv = self.handle_user_exception(e)
  File "/usr/local/lib/python3.8/site-packages/flask/app.py", line 1821, in handle_user_exception
    reraise(exc_type, exc_value, tb)
  File "/usr/local/lib/python3.8/site-packages/flask/_compat.py", line 39, in reraise
    raise value
  File "/usr/local/lib/python3.8/site-packages/flask/app.py", line 1950, in full_dispatch_request
    rv = self.dispatch_request()
  File "/usr/local/lib/python3.8/site-packages/flask/app.py", line 1936, in dispatch_request
    return self.view_functions[rule.endpoint](**req.view_args)
  File "/app/app/routes.py", line 64, in index
    return render_template('index.html', types=types, form=form)
  File "/usr/local/lib/python3.8/site-packages/flask/templating.py", line 137, in render_template
    return _render(
  File "/usr/local/lib/python3.8/site-packages/flask/templating.py", line 120, in _render
    rv = template.render(context)
  File "/usr/local/lib/python3.8/site-packages/jinja2/environment.py", line 1090, in render
    self.environment.handle_exception()
  File "/usr/local/lib/python3.8/site-packages/jinja2/environment.py", line 832, in handle_exception
    reraise(*rewrite_traceback_stack(source=source))
  File "/usr/local/lib/python3.8/site-packages/jinja2/_compat.py", line 28, in reraise
    raise value.with_traceback(tb)
  File "/app/app/templates/index.html", line 1, in top-level template code
    {% extends 'base.html' %}
  File "/app/app/templates/base.html", line 14, in top-level template code
    <a class="nav-link" href="{{ url_for('main.user_profile') }}">Profile</a>
  File "/usr/local/lib/python3.8/site-packages/flask/helpers.py", line 370, in url_for
    return appctx.app.handle_url_build_error(error, endpoint, values)
  File "/usr/local/lib/python3.8/site-packages/flask/app.py", line 2216, in handle_url_build_error
    reraise(exc_type, exc_value, tb)
  File "/usr/local/lib/python3.8/site-packages/flask/_compat.py", line 39, in reraise
    raise value
  File "/usr/local/lib/python3.8/site-packages/flask/helpers.py", line 357, in url_for
    rv = url_adapter.build(
  File "/usr/local/lib/python3.8/site-packages/werkzeug/routing.py", line 2179, in build
    raise BuildError(endpoint, values, method, self)
werkzeug.routing.BuildError: Could not build url for endpoint 'main.user_profile'. Did you forget to specify values ['username']?
[2024-09-14 15:10:49,995] {/usr/local/lib/python3.8/site-packages/flask/app.py:1891} ERROR - Exception on / [GET]
Traceback (most recent call last):
  File "/usr/local/lib/python3.8/site-packages/flask/app.py", line 2447, in wsgi_app
    response = self.full_dispatch_request()
  File "/usr/local/lib/python3.8/site-packages/flask/app.py", line 1952, in full_dispatch_request
    rv = self.handle_user_exception(e)
  File "/usr/local/lib/python3.8/site-packages/flask/app.py", line 1821, in handle_user_exception
    reraise(exc_type, exc_value, tb)
  File "/usr/local/lib/python3.8/site-packages/flask/_compat.py", line 39, in reraise
    raise value
  File "/usr/local/lib/python3.8/site-packages/flask/app.py", line 1950, in full_dispatch_request
    rv = self.dispatch_request()
  File "/usr/local/lib/python3.8/site-packages/flask/app.py", line 1936, in dispatch_request
    return self.view_functions[rule.endpoint](**req.view_args)
  File "/app/app/routes.py", line 64, in index
    return render_template('index.html', types=types, form=form)
  File "/usr/local/lib/python3.8/site-packages/flask/templating.py", line 137, in render_template
    return _render(
  File "/usr/local/lib/python3.8/site-packages/flask/templating.py", line 120, in _render
    rv = template.render(context)
  File "/usr/local/lib/python3.8/site-packages/jinja2/environment.py", line 1090, in render
    self.environment.handle_exception()
  File "/usr/local/lib/python3.8/site-packages/jinja2/environment.py", line 832, in handle_exception
    reraise(*rewrite_traceback_stack(source=source))
  File "/usr/local/lib/python3.8/site-packages/jinja2/_compat.py", line 28, in reraise
    raise value.with_traceback(tb)
  File "/app/app/templates/index.html", line 1, in top-level template code
    {% extends 'base.html' %}
  File "/app/app/templates/base.html", line 14, in top-level template code
    <a class="nav-link" href="{{ url_for('main.user_profile') }}">Profile</a>
  File "/usr/local/lib/python3.8/site-packages/flask/helpers.py", line 370, in url_for
    return appctx.app.handle_url_build_error(error, endpoint, values)
  File "/usr/local/lib/python3.8/site-packages/flask/app.py", line 2216, in handle_url_build_error
    reraise(exc_type, exc_value, tb)
  File "/usr/local/lib/python3.8/site-packages/flask/_compat.py", line 39, in reraise
    raise value
  File "/usr/local/lib/python3.8/site-packages/flask/helpers.py", line 357, in url_for
    rv = url_adapter.build(
  File "/usr/local/lib/python3.8/site-packages/werkzeug/routing.py", line 2179, in build
    raise BuildError(endpoint, values, method, self)
werkzeug.routing.BuildError: Could not build url for endpoint 'main.user_profile'. Did you forget to specify values ['username']?
[2024-09-14 15:10:50,864] {/usr/local/lib/python3.8/site-packages/flask/app.py:1891} ERROR - Exception on / [GET]
Traceback (most recent call last):
  File "/usr/local/lib/python3.8/site-packages/flask/app.py", line 2447, in wsgi_app
    response = self.full_dispatch_request()
  File "/usr/local/lib/python3.8/site-packages/flask/app.py", line 1952, in full_dispatch_request
    rv = self.handle_user_exception(e)
  File "/usr/local/lib/python3.8/site-packages/flask/app.py", line 1821, in handle_user_exception
    reraise(exc_type, exc_value, tb)
  File "/usr/local/lib/python3.8/site-packages/flask/_compat.py", line 39, in reraise
    raise value
  File "/usr/local/lib/python3.8/site-packages/flask/app.py", line 1950, in full_dispatch_request
    rv = self.dispatch_request()
  File "/usr/local/lib/python3.8/site-packages/flask/app.py", line 1936, in dispatch_request
    return self.view_functions[rule.endpoint](**req.view_args)
  File "/app/app/routes.py", line 64, in index
    return render_template('index.html', types=types, form=form)
  File "/usr/local/lib/python3.8/site-packages/flask/templating.py", line 137, in render_template
    return _render(
  File "/usr/local/lib/python3.8/site-packages/flask/templating.py", line 120, in _render
    rv = template.render(context)
  File "/usr/local/lib/python3.8/site-packages/jinja2/environment.py", line 1090, in render
    self.environment.handle_exception()
  File "/usr/local/lib/python3.8/site-packages/jinja2/environment.py", line 832, in handle_exception
    reraise(*rewrite_traceback_stack(source=source))
  File "/usr/local/lib/python3.8/site-packages/jinja2/_compat.py", line 28, in reraise
    raise value.with_traceback(tb)
  File "/app/app/templates/index.html", line 1, in top-level template code
    {% extends 'base.html' %}
  File "/app/app/templates/base.html", line 14, in top-level template code
    <a class="nav-link" href="{{ url_for('main.user_profile') }}">Profile</a>
  File "/usr/local/lib/python3.8/site-packages/flask/helpers.py", line 370, in url_for
    return appctx.app.handle_url_build_error(error, endpoint, values)
  File "/usr/local/lib/python3.8/site-packages/flask/app.py", line 2216, in handle_url_build_error
    reraise(exc_type, exc_value, tb)
  File "/usr/local/lib/python3.8/site-packages/flask/_compat.py", line 39, in reraise
    raise value
  File "/usr/local/lib/python3.8/site-packages/flask/helpers.py", line 357, in url_for
    rv = url_adapter.build(
  File "/usr/local/lib/python3.8/site-packages/werkzeug/routing.py", line 2179, in build
    raise BuildError(endpoint, values, method, self)
werkzeug.routing.BuildError: Could not build url for endpoint 'main.user_profile'. Did you forget to specify values ['username']?
[2024-09-14 15:11:19,822] {/usr/local/lib/python3.8/site-packages/flask/app.py:1891} ERROR - Exception on / [GET]
Traceback (most recent call last):
  File "/usr/local/lib/python3.8/site-packages/flask/app.py", line 2447, in wsgi_app
    response = self.full_dispatch_request()
  File "/usr/local/lib/python3.8/site-packages/flask/app.py", line 1952, in full_dispatch_request
    rv = self.handle_user_exception(e)
  File "/usr/local/lib/python3.8/site-packages/flask/app.py", line 1821, in handle_user_exception
    reraise(exc_type, exc_value, tb)
  File "/usr/local/lib/python3.8/site-packages/flask/_compat.py", line 39, in reraise
    raise value
  File "/usr/local/lib/python3.8/site-packages/flask/app.py", line 1950, in full_dispatch_request
    rv = self.dispatch_request()
  File "/usr/local/lib/python3.8/site-packages/flask/app.py", line 1936, in dispatch_request
    return self.view_functions[rule.endpoint](**req.view_args)
  File "/app/app/routes.py", line 64, in index
    return render_template('index.html', types=types, form=form)
  File "/usr/local/lib/python3.8/site-packages/flask/templating.py", line 137, in render_template
    return _render(
  File "/usr/local/lib/python3.8/site-packages/flask/templating.py", line 120, in _render
    rv = template.render(context)
  File "/usr/local/lib/python3.8/site-packages/jinja2/environment.py", line 1090, in render
    self.environment.handle_exception()
  File "/usr/local/lib/python3.8/site-packages/jinja2/environment.py", line 832, in handle_exception
    reraise(*rewrite_traceback_stack(source=source))
  File "/usr/local/lib/python3.8/site-packages/jinja2/_compat.py", line 28, in reraise
    raise value.with_traceback(tb)
  File "/app/app/templates/index.html", line 1, in top-level template code
    {% extends 'base.html' %}
  File "/app/app/templates/base.html", line 14, in top-level template code
    <a class="nav-link" href="{{ url_for('main.user_profile') }}">Profile</a>
  File "/usr/local/lib/python3.8/site-packages/flask/helpers.py", line 370, in url_for
    return appctx.app.handle_url_build_error(error, endpoint, values)
  File "/usr/local/lib/python3.8/site-packages/flask/app.py", line 2216, in handle_url_build_error
    reraise(exc_type, exc_value, tb)
  File "/usr/local/lib/python3.8/site-packages/flask/_compat.py", line 39, in reraise
    raise value
  File "/usr/local/lib/python3.8/site-packages/flask/helpers.py", line 357, in url_for
    rv = url_adapter.build(
  File "/usr/local/lib/python3.8/site-packages/werkzeug/routing.py", line 2179, in build
    raise BuildError(endpoint, values, method, self)
werkzeug.routing.BuildError: Could not build url for endpoint 'main.user_profile'. Did you forget to specify values ['username']?
[2024-09-14 15:13:51,447] {/usr/local/lib/python3.8/site-packages/flask/app.py:1891} ERROR - Exception on /user/test [GET]
Traceback (most recent call last):
  File "/usr/local/lib/python3.8/site-packages/flask/app.py", line 2447, in wsgi_app
    response = self.full_dispatch_request()
  File "/usr/local/lib/python3.8/site-packages/flask/app.py", line 1952, in full_dispatch_request
    rv = self.handle_user_exception(e)
  File "/usr/local/lib/python3.8/site-packages/flask/app.py", line 1821, in handle_user_exception
    reraise(exc_type, exc_value, tb)
  File "/usr/local/lib/python3.8/site-packages/flask/_compat.py", line 39, in reraise
    raise value
  File "/usr/local/lib/python3.8/site-packages/flask/app.py", line 1950, in full_dispatch_request
    rv = self.dispatch_request()
  File "/usr/local/lib/python3.8/site-packages/flask/app.py", line 1936, in dispatch_request
    return self.view_functions[rule.endpoint](**req.view_args)
  File "/usr/local/lib/python3.8/site-packages/flask_login/utils.py", line 291, in decorated_view
    return func(*args, **kwargs)
  File "/app/app/routes.py", line 127, in user_profile
    return render_template('profile.html', user=user)
  File "/usr/local/lib/python3.8/site-packages/flask/templating.py", line 138, in render_template
    ctx.app.jinja_env.get_or_select_template(template_name_or_list),
  File "/usr/local/lib/python3.8/site-packages/jinja2/environment.py", line 930, in get_or_select_template
    return self.get_template(template_name_or_list, parent, globals)
  File "/usr/local/lib/python3.8/site-packages/jinja2/environment.py", line 883, in get_template
    return self._load_template(name, self.make_globals(globals))
  File "/usr/local/lib/python3.8/site-packages/jinja2/environment.py", line 857, in _load_template
    template = self.loader.load(self, name, globals)
  File "/usr/local/lib/python3.8/site-packages/jinja2/loaders.py", line 115, in load
    source, filename, uptodate = self.get_source(environment, name)
  File "/usr/local/lib/python3.8/site-packages/flask/templating.py", line 60, in get_source
    return self._get_source_fast(environment, template)
  File "/usr/local/lib/python3.8/site-packages/flask/templating.py", line 89, in _get_source_fast
    raise TemplateNotFound(template)
jinja2.exceptions.TemplateNotFound: profile.html
[2024-09-14 15:23:33,901] {/usr/local/lib/python3.8/site-packages/flask/app.py:1891} ERROR - Exception on /user/test [GET]
Traceback (most recent call last):
  File "/usr/local/lib/python3.8/site-packages/flask/app.py", line 2447, in wsgi_app
    response = self.full_dispatch_request()
  File "/usr/local/lib/python3.8/site-packages/flask/app.py", line 1952, in full_dispatch_request
    rv = self.handle_user_exception(e)
  File "/usr/local/lib/python3.8/site-packages/flask/app.py", line 1821, in handle_user_exception
    reraise(exc_type, exc_value, tb)
  File "/usr/local/lib/python3.8/site-packages/flask/_compat.py", line 39, in reraise
    raise value
  File "/usr/local/lib/python3.8/site-packages/flask/app.py", line 1950, in full_dispatch_request
    rv = self.dispatch_request()
  File "/usr/local/lib/python3.8/site-packages/flask/app.py", line 1936, in dispatch_request
    return self.view_functions[rule.endpoint](**req.view_args)
  File "/usr/local/lib/python3.8/site-packages/flask_login/utils.py", line 291, in decorated_view
    return func(*args, **kwargs)
  File "/app/app/routes.py", line 127, in user_profile
    return render_template('profile.html', user=user)
  File "/usr/local/lib/python3.8/site-packages/flask/templating.py", line 137, in render_template
    return _render(
  File "/usr/local/lib/python3.8/site-packages/flask/templating.py", line 120, in _render
    rv = template.render(context)
  File "/usr/local/lib/python3.8/site-packages/jinja2/environment.py", line 1090, in render
    self.environment.handle_exception()
  File "/usr/local/lib/python3.8/site-packages/jinja2/environment.py", line 832, in handle_exception
    reraise(*rewrite_traceback_stack(source=source))
  File "/usr/local/lib/python3.8/site-packages/jinja2/_compat.py", line 28, in reraise
    raise value.with_traceback(tb)
  File "/app/app/templates/profile.html", line 1, in top-level template code
    {% extends "base.html" %}
  File "/app/app/templates/base.html", line 47, in top-level template code
    {% block content %}{% endblock %}
  File "/app/app/templates/profile.html", line 8, in block "content"
    {{ form.hidden_tag() }}
  File "/usr/local/lib/python3.8/site-packages/jinja2/environment.py", line 471, in getattr
    return getattr(obj, attribute)
jinja2.exceptions.UndefinedError: 'form' is undefined
[2024-09-14 15:23:37,001] {/usr/local/lib/python3.8/site-packages/flask/app.py:1891} ERROR - Exception on /user/test [GET]
Traceback (most recent call last):
  File "/usr/local/lib/python3.8/site-packages/flask/app.py", line 2447, in wsgi_app
    response = self.full_dispatch_request()
  File "/usr/local/lib/python3.8/site-packages/flask/app.py", line 1952, in full_dispatch_request
    rv = self.handle_user_exception(e)
  File "/usr/local/lib/python3.8/site-packages/flask/app.py", line 1821, in handle_user_exception
    reraise(exc_type, exc_value, tb)
  File "/usr/local/lib/python3.8/site-packages/flask/_compat.py", line 39, in reraise
    raise value
  File "/usr/local/lib/python3.8/site-packages/flask/app.py", line 1950, in full_dispatch_request
    rv = self.dispatch_request()
  File "/usr/local/lib/python3.8/site-packages/flask/app.py", line 1936, in dispatch_request
    return self.view_functions[rule.endpoint](**req.view_args)
  File "/usr/local/lib/python3.8/site-packages/flask_login/utils.py", line 291, in decorated_view
    return func(*args, **kwargs)
  File "/app/app/routes.py", line 127, in user_profile
    return render_template('profile.html', user=user)
  File "/usr/local/lib/python3.8/site-packages/flask/templating.py", line 137, in render_template
    return _render(
  File "/usr/local/lib/python3.8/site-packages/flask/templating.py", line 120, in _render
    rv = template.render(context)
  File "/usr/local/lib/python3.8/site-packages/jinja2/environment.py", line 1090, in render
    self.environment.handle_exception()
  File "/usr/local/lib/python3.8/site-packages/jinja2/environment.py", line 832, in handle_exception
    reraise(*rewrite_traceback_stack(source=source))
  File "/usr/local/lib/python3.8/site-packages/jinja2/_compat.py", line 28, in reraise
    raise value.with_traceback(tb)
  File "/app/app/templates/profile.html", line 1, in top-level template code
    {% extends "base.html" %}
  File "/app/app/templates/base.html", line 47, in top-level template code
    {% block content %}{% endblock %}
  File "/app/app/templates/profile.html", line 8, in block "content"
    {{ form.hidden_tag() }}
  File "/usr/local/lib/python3.8/site-packages/jinja2/environment.py", line 471, in getattr
    return getattr(obj, attribute)
jinja2.exceptions.UndefinedError: 'form' is undefined
[2024-09-14 15:32:15,391] {/usr/local/lib/python3.8/site-packages/flask/app.py:1891} ERROR - Exception on /user/test [GET]
Traceback (most recent call last):
  File "/usr/local/lib/python3.8/site-packages/flask/app.py", line 2447, in wsgi_app
    response = self.full_dispatch_request()
  File "/usr/local/lib/python3.8/site-packages/flask/app.py", line 1952, in full_dispatch_request
    rv = self.handle_user_exception(e)
  File "/usr/local/lib/python3.8/site-packages/flask/app.py", line 1821, in handle_user_exception
    reraise(exc_type, exc_value, tb)
  File "/usr/local/lib/python3.8/site-packages/flask/_compat.py", line 39, in reraise
    raise value
  File "/usr/local/lib/python3.8/site-packages/flask/app.py", line 1950, in full_dispatch_request
    rv = self.dispatch_request()
  File "/usr/local/lib/python3.8/site-packages/flask/app.py", line 1936, in dispatch_request
    return self.view_functions[rule.endpoint](**req.view_args)
  File "/usr/local/lib/python3.8/site-packages/flask_login/utils.py", line 291, in decorated_view
    return func(*args, **kwargs)
  File "/app/app/routes.py", line 128, in user_profile
    return render_template('profile.html', user=user)
  File "/usr/local/lib/python3.8/site-packages/flask/templating.py", line 137, in render_template
    return _render(
  File "/usr/local/lib/python3.8/site-packages/flask/templating.py", line 120, in _render
    rv = template.render(context)
  File "/usr/local/lib/python3.8/site-packages/jinja2/environment.py", line 1090, in render
    self.environment.handle_exception()
  File "/usr/local/lib/python3.8/site-packages/jinja2/environment.py", line 832, in handle_exception
    reraise(*rewrite_traceback_stack(source=source))
  File "/usr/local/lib/python3.8/site-packages/jinja2/_compat.py", line 28, in reraise
    raise value.with_traceback(tb)
  File "/app/app/templates/profile.html", line 1, in top-level template code
    {% extends "base.html" %}
  File "/app/app/templates/base.html", line 47, in top-level template code
    {% block content %}{% endblock %}
  File "/app/app/templates/profile.html", line 7, in block "content"
    {{ form.hidden_tag() }}
  File "/usr/local/lib/python3.8/site-packages/jinja2/environment.py", line 471, in getattr
    return getattr(obj, attribute)
jinja2.exceptions.UndefinedError: 'form' is undefined
